Loaded .env file from: D:\Scripts\analyse\Telemark\Python\token.env
X_FUNCTIONS_KEY loaded successfully.
Loaded .env file from: D:\Scripts\analyse\Telemark\Python\token.env
GITHUB_TOKEN loaded successfully.
Request error in Sysselsetting i kommunene (new codes): 400 Client Error: Bad Request for url: https://data.ssb.no/api/v0/no/table/06445/
Error occurred: 400 Client Error: Bad Request for url: https://data.ssb.no/api/v0/no/table/06445/
Email notifications disabled. Errors in sysselsetting_i_kommunene.py were not sent.


Errors:
Traceback (most recent call last):
  File "D:\Scripts\analyse\Telemark\Python\Queries/03_Arbeid_og_naeringsliv/Arbeidsliv/Sysselsetting/sysselsetting_i_kommunene.py", line 130, in <module>
    df = fetch_data(
  File "D:\Scripts\analyse\Telemark\Python\Helper_scripts\utility_functions.py", line 48, in fetch_data
    response.raise_for_status()
  File "C:\Users\_eve1509\AppData\Local\anaconda3\envs\analyse\lib\site-packages\requests\models.py", line 1024, in raise_for_status
    raise HTTPError(http_error_msg, response=self)
requests.exceptions.HTTPError: 400 Client Error: Bad Request for url: https://data.ssb.no/api/v0/no/table/06445/

During handling of the above exception, another exception occurred:

Traceback (most recent call last):
  File "D:\Scripts\analyse\Telemark\Python\Queries/03_Arbeid_og_naeringsliv/Arbeidsliv/Sysselsetting/sysselsetting_i_kommunene.py", line 151, in <module>
    raise RuntimeError(
RuntimeError: A critical error occurred during data fetching, stopping execution.

ERROR conda.cli.main_run:execute(125): `conda run python D:\Scripts\analyse\Telemark\Python\Queries/03_Arbeid_og_naeringsliv/Arbeidsliv/Sysselsetting/sysselsetting_i_kommunene.py` failed. (See above for error)
