Loaded .env file from: D:\Scripts\analyse\Telemark\Python\token.env
X_FUNCTIONS_KEY loaded successfully.
Loaded .env file from: D:\Scripts\analyse\Telemark\Python\token.env
GITHUB_TOKEN loaded successfully.
Downloading file from Enhetsregisteret...
Total file size: 173.1 MB
Writing downloaded content to file...

Download progress: [                                                  ] 8192/181475238 bytes
Download progress: [                                                  ] 16384/181475238 bytes
Download progress: [                                                  ] 24576/181475238 bytes
Download progress: [                                                  ] 32768/181475238 bytes
Download progress: [                                                  ] 40960/181475238 bytes
Download progress: [                                                  ] 49152/181475238 bytes
Download progress: [                                                  ] 57344/181475238 bytes
Download progress: [                                                  ] 65536/181475238 bytes
Download progress: [                                                  ] 73728/181475238 bytes
Download progress: [                                                  ] 81920/181475238 bytes
Download progress: [                                                  ] 90112/181475238 bytes
Download progress: [                                                  ] 98304/181475238 bytes
Download progress: [                                                  ] 106496/181475238 bytesEmail notifications disabled. Errors in enhetsregisteret_hovedenheter.py were not sent.


Errors:
Traceback (most recent call last):
  File "C:\Users\_eve1509\AppData\Local\anaconda3\envs\analyse\lib\site-packages\urllib3\response.py", line 748, in _error_catcher
    yield
  File "C:\Users\_eve1509\AppData\Local\anaconda3\envs\analyse\lib\site-packages\urllib3\response.py", line 894, in _raw_read
    raise IncompleteRead(self._fp_bytes_read, self.length_remaining)
urllib3.exceptions.IncompleteRead: IncompleteRead(114015 bytes read, 181361223 more expected)

The above exception was the direct cause of the following exception:

Traceback (most recent call last):
  File "C:\Users\_eve1509\AppData\Local\anaconda3\envs\analyse\lib\site-packages\requests\models.py", line 820, in generate
    yield from self.raw.stream(chunk_size, decode_content=True)
  File "C:\Users\_eve1509\AppData\Local\anaconda3\envs\analyse\lib\site-packages\urllib3\response.py", line 1060, in stream
    data = self.read(amt=amt, decode_content=decode_content)
  File "C:\Users\_eve1509\AppData\Local\anaconda3\envs\analyse\lib\site-packages\urllib3\response.py", line 977, in read
    data = self._raw_read(amt)
  File "C:\Users\_eve1509\AppData\Local\anaconda3\envs\analyse\lib\site-packages\urllib3\response.py", line 902, in _raw_read
    self._fp.close()
  File "C:\Users\_eve1509\AppData\Local\anaconda3\envs\analyse\lib\contextlib.py", line 131, in __exit__
    self.gen.throw(type, value, traceback)
  File "C:\Users\_eve1509\AppData\Local\anaconda3\envs\analyse\lib\site-packages\urllib3\response.py", line 772, in _error_catcher
    raise ProtocolError(arg, e) from e
urllib3.exceptions.ProtocolError: ('Connection broken: IncompleteRead(114015 bytes read, 181361223 more expected)', IncompleteRead(114015 bytes read, 181361223 more expected))

During handling of the above exception, another exception occurred:

Traceback (most recent call last):
  File "D:\Scripts\analyse\Telemark\Python\Queries/03_Arbeid_og_naeringsliv/NÃÂ¦ringsliv/Virksomheter/enhetsregisteret_hovedenheter.py", line 51, in <module>
    for data in response.iter_content(chunk_size=8192):
  File "C:\Users\_eve1509\AppData\Local\anaconda3\envs\analyse\lib\site-packages\requests\models.py", line 822, in generate
    raise ChunkedEncodingError(e)
requests.exceptions.ChunkedEncodingError: ('Connection broken: IncompleteRead(114015 bytes read, 181361223 more expected)', IncompleteRead(114015 bytes read, 181361223 more expected))

During handling of the above exception, another exception occurred:

Traceback (most recent call last):
  File "D:\Scripts\analyse\Telemark\Python\Queries/03_Arbeid_og_naeringsliv/NÃÂ¦ringsliv/Virksomheter/enhetsregisteret_hovedenheter.py", line 87, in <module>
    raise RuntimeError(f"Download/extraction failed: {str(dl_error)}")
RuntimeError: Download/extraction failed: ('Connection broken: IncompleteRead(114015 bytes read, 181361223 more expected)', IncompleteRead(114015 bytes read, 181361223 more expected))

During handling of the above exception, another exception occurred:

Traceback (most recent call last):
  File "D:\Scripts\analyse\Telemark\Python\Queries/03_Arbeid_og_naeringsliv/NÃÂ¦ringsliv/Virksomheter/enhetsregisteret_hovedenheter.py", line 245, in <module>
    raise RuntimeError("A critical error occurred during script execution.")
RuntimeError: A critical error occurred during script execution.

ERROR conda.cli.main_run:execute(125): `conda run python D:\Scripts\analyse\Telemark\Python\Queries/03_Arbeid_og_naeringsliv/NÃ¦ringsliv/Virksomheter/enhetsregisteret_hovedenheter.py` failed. (See above for error)
