Loaded .env file from: C:\Users\eve1509\OneDrive - Telemark fylkeskommune\Github\Telemark\Python\token.env

X_FUNCTIONS_KEY loaded successfully.

Loaded .env file from: C:\Users\eve1509\OneDrive - Telemark fylkeskommune\Github\Telemark\Python\token.env

GITHUB_TOKEN loaded successfully.

Script starting...

Working with file: Data/04_Klima og ressursforvaltning/Kraft og energi/Kraftpriser/entso-e/strompriser.csv

Checking for existing data...

Type of existing_df: <class 'pandas.core.frame.DataFrame'>

Latest date in existing data: 2025-01-14 00:00:00

Found 1476 existing records

All prices are already up to date (up until yesterday), no new data to fetch.



Errors:
Traceback (most recent call last):

  File "C:\Users\eve1509\OneDrive - Telemark fylkeskommune\Github\Telemark\Python\Queries/04_Klima_og_energi/Kraft og energi/Strompriser/strompriser.py", line 186, in <module>

    daily_avg.columns = ["time", "EUR/MWh", "kurs", "NOK/MWh"]

  File "C:\Users\eve1509\.conda\envs\analyse\lib\site-packages\pandas\core\generic.py", line 6002, in __setattr__

    return object.__setattr__(self, name, value)

  File "pandas\_libs\properties.pyx", line 69, in pandas._libs.properties.AxisProperty.__set__

  File "C:\Users\eve1509\.conda\envs\analyse\lib\site-packages\pandas\core\generic.py", line 730, in _set_axis

    self._mgr.set_axis(axis, labels)

  File "C:\Users\eve1509\.conda\envs\analyse\lib\site-packages\pandas\core\internals\managers.py", line 225, in set_axis

    self._validate_set_axis(axis, new_labels)

  File "C:\Users\eve1509\.conda\envs\analyse\lib\site-packages\pandas\core\internals\base.py", line 70, in _validate_set_axis

    raise ValueError(

ValueError: Length mismatch: Expected axis has 5 elements, new values have 4 elements


ERROR conda.cli.main_run:execute(124): `conda run python C:\Users\eve1509\OneDrive - Telemark fylkeskommune\Github\Telemark\Python\Queries/04_Klima_og_energi/Kraft og energi/Strompriser/strompriser.py` failed. (See above for error)
